Traceback (most recent call last):
  File "/home3/s3799042/lc0_venv2/lib/python3.11/site-packages/huggingface_hub/utils/_http.py", line 409, in hf_raise_for_status
    response.raise_for_status()
  File "/home3/s3799042/lc0_venv2/lib/python3.11/site-packages/requests/models.py", line 1024, in raise_for_status
    raise HTTPError(http_error_msg, response=self)
requests.exceptions.HTTPError: 401 Client Error: Unauthorized for url: https://huggingface.co/trocr-hebrew-finetuned/resolve/main/config.json

The above exception was the direct cause of the following exception:

Traceback (most recent call last):
  File "/home3/s3799042/lc0_venv2/lib/python3.11/site-packages/transformers/utils/hub.py", line 424, in cached_files
    hf_hub_download(
  File "/home3/s3799042/lc0_venv2/lib/python3.11/site-packages/huggingface_hub/utils/_validators.py", line 114, in _inner_fn
    return fn(*args, **kwargs)
           ^^^^^^^^^^^^^^^^^^^
  File "/home3/s3799042/lc0_venv2/lib/python3.11/site-packages/huggingface_hub/file_download.py", line 961, in hf_hub_download
    return _hf_hub_download_to_cache_dir(
           ^^^^^^^^^^^^^^^^^^^^^^^^^^^^^^
  File "/home3/s3799042/lc0_venv2/lib/python3.11/site-packages/huggingface_hub/file_download.py", line 1068, in _hf_hub_download_to_cache_dir
    _raise_on_head_call_error(head_call_error, force_download, local_files_only)
  File "/home3/s3799042/lc0_venv2/lib/python3.11/site-packages/huggingface_hub/file_download.py", line 1596, in _raise_on_head_call_error
    raise head_call_error
  File "/home3/s3799042/lc0_venv2/lib/python3.11/site-packages/huggingface_hub/file_download.py", line 1484, in _get_metadata_or_catch_error
    metadata = get_hf_file_metadata(
               ^^^^^^^^^^^^^^^^^^^^^
  File "/home3/s3799042/lc0_venv2/lib/python3.11/site-packages/huggingface_hub/utils/_validators.py", line 114, in _inner_fn
    return fn(*args, **kwargs)
           ^^^^^^^^^^^^^^^^^^^
  File "/home3/s3799042/lc0_venv2/lib/python3.11/site-packages/huggingface_hub/file_download.py", line 1401, in get_hf_file_metadata
    r = _request_wrapper(
        ^^^^^^^^^^^^^^^^^
  File "/home3/s3799042/lc0_venv2/lib/python3.11/site-packages/huggingface_hub/file_download.py", line 285, in _request_wrapper
    response = _request_wrapper(
               ^^^^^^^^^^^^^^^^^
  File "/home3/s3799042/lc0_venv2/lib/python3.11/site-packages/huggingface_hub/file_download.py", line 309, in _request_wrapper
    hf_raise_for_status(response)
  File "/home3/s3799042/lc0_venv2/lib/python3.11/site-packages/huggingface_hub/utils/_http.py", line 459, in hf_raise_for_status
    raise _format(RepositoryNotFoundError, message, response) from e
huggingface_hub.errors.RepositoryNotFoundError: 401 Client Error. (Request ID: Root=1-681e1f5d-6a98d3a94f8f271906fe3984;3178926a-b9e4-4131-a63a-7a0f1405c3a3)

Repository Not Found for url: https://huggingface.co/trocr-hebrew-finetuned/resolve/main/config.json.
Please make sure you specified the correct `repo_id` and `repo_type`.
If you are trying to access a private or gated repo, make sure you are authenticated. For more details, see https://huggingface.co/docs/huggingface_hub/authentication
Invalid username or password.

The above exception was the direct cause of the following exception:

Traceback (most recent call last):
  File "/home3/s3799042/DeadSeaScrolls/huggingface_ocr/huggingface_ocr.py", line 102, in <module>
    model = VisionEncoderDecoderModel.from_pretrained('trocr-hebrew-finetuned')
            ^^^^^^^^^^^^^^^^^^^^^^^^^^^^^^^^^^^^^^^^^^^^^^^^^^^^^^^^^^^^^^^^^^^
  File "/home3/s3799042/lc0_venv2/lib/python3.11/site-packages/transformers/models/vision_encoder_decoder/modeling_vision_encoder_decoder.py", line 370, in from_pretrained
    return super().from_pretrained(pretrained_model_name_or_path, *model_args, **kwargs)
           ^^^^^^^^^^^^^^^^^^^^^^^^^^^^^^^^^^^^^^^^^^^^^^^^^^^^^^^^^^^^^^^^^^^^^^^^^^^^^
  File "/home3/s3799042/lc0_venv2/lib/python3.11/site-packages/transformers/modeling_utils.py", line 279, in _wrapper
    return func(*args, **kwargs)
           ^^^^^^^^^^^^^^^^^^^^^
  File "/home3/s3799042/lc0_venv2/lib/python3.11/site-packages/transformers/modeling_utils.py", line 4083, in from_pretrained
    resolved_config_file = cached_file(
                           ^^^^^^^^^^^^
  File "/home3/s3799042/lc0_venv2/lib/python3.11/site-packages/transformers/utils/hub.py", line 266, in cached_file
    file = cached_files(path_or_repo_id=path_or_repo_id, filenames=[filename], **kwargs)
           ^^^^^^^^^^^^^^^^^^^^^^^^^^^^^^^^^^^^^^^^^^^^^^^^^^^^^^^^^^^^^^^^^^^^^^^^^^^^^
  File "/home3/s3799042/lc0_venv2/lib/python3.11/site-packages/transformers/utils/hub.py", line 456, in cached_files
    raise OSError(
OSError: trocr-hebrew-finetuned is not a local folder and is not a valid model identifier listed on 'https://huggingface.co/models'
If this is a private repository, make sure to pass a token having permission to this repo either by logging in with `huggingface-cli login` or by passing `token=<your_token>`
